Workbook

Sheet Leeme
A1: Matriz de revisión de literatura
A2: Trabajo de grado: Identificación preventiva de información sensible en el uso empresarial de IA generativa mediante un enfoque híbrido de NER y expresiones regulares. Autor: Andrés Felipe Saldarriaga Becerra.
A4: Propósito
A5: Esta matriz documenta la revisión de literatura que sustenta el objetivo específico 1: la taxonomía de información sensible, la asignación de un detector a cada tipo de entidad, las métricas de evaluación y los vacíos que justifican el trabajo. Cada decisión de la tesis que se apoya en la literatura remite a estudios concretos de la hoja Cribado.
A7: Búsqueda
A8: Fuente | B8: Scopus (exportación CSV con 126 registros)
A9: Campos | B9: Título, resumen y palabras clave
A10: Ecuación | B10: TITLE-ABS-KEY(("personally identifiable information" OR PII OR "sensitive information" OR "sensitive data") AND ("named entity recognition" OR NER OR "regular expression*" OR regex) AND (detect* OR anonym* OR de-identif* OR mask* OR redact*) AND (text* OR document* OR prompt*)) AND PUBYEAR > 2021 AND PUBYEAR < 2028
A11: Fecha de la búsqueda replicada | B11: 10 de octubre de 2026
A12: Registros | B12: 126 (dos con año 2027, ya indexados antes de su publicación definitiva)
A14: Resultado del cribado
A15: Decisión | B15: Registros | C15: % del total | D15: Versión anterior
A16: Núcleo | B16: =COUNTIF(Cribado!$H$2:$H$127,A16) -> 85 | C16: =B16/$B$19 -> 0.67460317 | D16: 78
A17: Complementario | B17: =COUNTIF(Cribado!$H$2:$H$127,A17) -> 25 | C17: =B17/$B$19 -> 0.1984127 | D17: 30
A18: Excluido | B18: =COUNTIF(Cribado!$H$2:$H$127,A18) -> 16 | C18: =B18/$B$19 -> 0.12698413 | D18: 18
A19: Total | B19: =SUM(B16:B18) -> 126 | D19: =SUM(D16:D18) -> 126
A20: Decisiones que cambiaron frente a la versión anterior | B20: =SUMPRODUCT(--(Cribado!$H$2:$H$127<>Cribado!$K$2:$K$127)) -> 24
A21: Estudios verificados con el texto completo | B21: =COUNTIF(Cribado!$AQ$2:$AQ$127,"Abstract y texto completo") -> 10
A23: Cómo está organizada
A24: Protocolo | B24: Preguntas de la revisión, criterios de decisión con su código y significado de cada columna de la hoja Cribado.
A25: Cribado | B25: Los 126 registros, uno por fila: decisión, código del criterio, justificación específica y extracción de técnicas, entidades, datos, métricas y rasgos de evaluación. La columna «Decisión en la versión anterior» aparece en rojo cuando la decisión cambió.
A26: Síntesis | B26: Conteos calculados con fórmulas sobre la hoja Cribado: decisiones por criterio y por año, técnicas, entidades, idiomas, dominios y rasgos de evaluación de los estudios núcleo.
A27: Taxonomía | B27: Trazabilidad de las trece etiquetas de la Tabla 6 de la tesis: cuántos estudios núcleo las mencionan, qué estudios respaldan el detector asignado y cuándo la etiqueta se incluye por analogía, sin respaldo directo.
A28: Lectura_profunda | B28: Trece estudios clave revisados más allá del abstract: qué se verificó, sus resultados, la decisión de diseño que sustentan y qué se corrigió frente a lo que decía el abstract.
A29: Hallazgos | B29: Hallazgos de la revisión con su evidencia, su implicación para el diseño y la sección de la tesis donde se usan.
A31: Alcance y limitaciones
A32: • El cribado y la extracción de la hoja Cribado se basan en el título y el abstract de cada registro; una entidad o técnica se marca solo si el abstract la menciona de forma explícita. Por eso las columnas de entidades subestiman lo que los artículos contienen.
A33: • Diez estudios de la hoja Lectura_profunda se verificaron con el texto completo; en S090 y S012 solo se pudo revisar el repositorio y en S048 solo los metadatos. Esa evidencia se reporta aparte y no modifica las marcas basadas en el abstract.
A34: • La revisión la hizo un solo revisor; los criterios explícitos y la justificación de cada decisión permiten que otra persona la repita y la audite.
A35: • Los antecedentes identificados por fuera de Scopus (Chong et al., 2025; Carpentier et al., 2024; Pilán et al., 2022) no forman parte de los 126 registros y se señalan en la hoja Hallazgos.

Sheet Protocolo
A1: Protocolo de la revisión
A3: Preguntas de la revisión
A4: Pregunta | B4: Tema | C4: Pregunta | D4: Hoja donde se responde
A5: P1 | B5: Entidades | C5: ¿Qué tipos de información sensible detectan los trabajos y cómo los organizan? | D5: Taxonomía; Síntesis (entidades)
A6: P2 | B6: Técnicas | C6: ¿Qué técnicas se usan para cada tipo y cuándo combinan reglas con modelos? | D6: Síntesis (técnicas); Taxonomía; Hallazgos
A7: P3 | B7: Datos e idioma | C7: ¿Con qué datos, dominios e idiomas se evalúan, y cuánta evidencia hay en español? | D7: Síntesis (idiomas y dominios)
A8: P4 | B8: Evaluación | C8: ¿Qué métricas usan y cuántos trabajos miden la utilidad del texto protegido o la respuesta de un LLM? | D8: Síntesis (rasgos de evaluación); Hallazgos
A10: Criterios de decisión
A11: Código | B11: Decisión | C11: Se asigna cuando | D11: Ejemplos
A12: N | B12: Núcleo | C12: El estudio detecta, desidentifica, anonimiza, seudonimiza o enmascara información sensible en texto escrito y aporta evidencia sobre entidades, técnicas, datos o métricas. | D12: S026, S039, S090, S107
A13: C1 | B13: Complementario | C13: Privacidad y utilidad, sustitución o generación de datos sintéticos, sin foco en la detección de entidades. | D13: S041, S076, S104
A14: C2 | B14: Complementario | C14: Arquitectura, gobierno o control de acceso de sistemas con LLM, donde la detección es un componente secundario. | D14: S010, S023, S096
A15: C3 | B15: Complementario | C15: La detección se hace sobre texto extraído de imágenes o audio (OCR o reconocimiento de voz); aporta técnicas, pero no el escenario de texto escrito. | D15: S013, S033, S040
A16: C4 | B16: Complementario | C16: Ataques, análisis de riesgo o clasificación de documentos por sensibilidad, sin un mecanismo de protección. | D16: S032, S035, S060
A17: C5 | B17: Complementario | C17: Capítulo, marco general o herramienta amplia sin evaluación de la detección. | D17: S024, S055
A18: E1 | B18: Excluido | C18: No es un estudio primario: fe de erratas o presentación de actas de un congreso. | D18: S006, S092, S114
A19: E2 | B19: Excluido | C19: El problema principal es otro (phishing, vulnerabilidades web, inteligencia de amenazas, predicción judicial, análisis de fraude o de quejas); la privacidad es incidental. | D19: S020, S061, S073
A20: E3 | B20: Excluido | C20: La protección de datos personales es un paso menor de otro proceso y no se evalúa. | D20: S003
A21: El acceso abierto no se usó como criterio de exclusión. Las decisiones se tomaron con el título y el abstract.
A23: Columnas de la hoja Cribado
A24: Columna | B24: Valores | C24: Significado
A25: Decisión y Código | B25: Núcleo, Complementario, Excluido; N, C1–C5, E1–E3 | C25: Decisión del cribado y criterio que la sustenta.
A26: Grupo de dominio | B26: Diez grupos | C26: Agrupa el dominio libre para los conteos de la hoja Síntesis.
A27: Grupo de idioma | B27: Inglés; Español (solo o con otras lenguas); Otra lengua; Multilingüe; No indicado o no aplica | C27: Idioma de los datos evaluados según el abstract.
A28: Técnicas (siete columnas) | B28: X o vacío | C28: Se marca la técnica que el abstract menciona como parte del método o de la comparación.
A29: Híbrido (reglas + modelo) | B29: Sí / No (fórmula) | C29: Sí cuando el estudio combina regex o reglas con un modelo aprendido (ML clásico, transformer o LLM).
A30: Entidades (catorce columnas) | B30: X o vacío | C30: Se marca solo si el abstract nombra ese tipo de dato de forma explícita (por ejemplo, «phone numbers» para PHONE).
A31: Protege el texto antes de enviarlo a un servicio externo | B31: Sí / No | C31: El mecanismo actúa sobre el texto antes de que salga hacia un LLM u otro servicio (proxy, extensión de navegador, filtro previo).
A32: Evalúa la utilidad del texto protegido | B32: Sí / No | C32: Mide preservación semántica, desempeño de una tarea posterior o calidad del texto transformado.
A33: Evalúa la respuesta de un LLM | B33: Sí / No | C33: Mide la respuesta que genera un LLM a partir del texto protegido.
A34: Base de evidencia | B34: Abstract; Abstract y texto completo; Abstract y repositorio | C34: Indica si el estudio también se verificó con el texto completo o, cuando el artículo no estaba disponible, con su repositorio (hoja Lectura_profunda).

Sheet Cribado
A1: ID | B1: Autores | C1: Año | D1: Título | E1: Fuente | F1: Tipo de documento | G1: DOI | H1: Decisión | I1: Código | J1: Justificación (basada en el abstract) | K1: Decisión en la versión anterior | L1: Dominio | M1: Grupo de dominio | N1: Idioma de los datos | O1: Grupo de idioma | P1: Regex / reglas | Q1: Diccionarios / listas | R1: ML clásico o NER no transformer (CRF, BiLSTM, spaCy) | S1: Transformer (BERT y similares) | T1: LLM | U1: Herramienta existente (Presidio, Purview…) | V1: Otra técnica (embeddings, OCR, privacidad diferencial…) | W1: Híbrido (reglas + modelo) | X1: PER | Y1: EMAIL | Z1: PHONE | AA1: ADDRESS | AB1: ID_DOC | AC1: FIN_ID | AD1: DATE | AE1: LOC | AF1: ORG | AG1: CREDENTIAL / SECRET | AH1: NET_DIGITAL | AI1: URL | AJ1: DOC_REF | AK1: Atributo sensible semántico | AL1: Protege el texto antes de enviarlo a un servicio externo | AM1: Evalúa la utilidad del texto protegido | AN1: Evalúa la respuesta de un LLM | AO1: Datos / corpus | AP1: Métricas o resultados del abstract | AQ1: Base de evidencia | AR1: Abstract
A2: S001 | B2: Thakkar M.; Vora J.; Patel K.; Agrawal A.K.; Sorathiya Y. | C2: 2026 | D2: Implementation of an OSINT-Based Dark Web Monitoring Tool for Stolen Personally Identifiable Information (PII) | E2: GSEACT 2026 - 2026 IEEE Global Symposium on Emerging and Communication Technologies | F2: Conference paper | G2: 10.1109/GSEACT68539.2026.11620580 | H2: Núcleo | I2: N | J2: Detecta PII expuesta en texto extraído de la dark web con un motor híbrido de regex, NER y Presidio; útil como evidencia de la combinación con Presidio. | K2: Núcleo | L2: Web / ciberseguridad | M2: Ciberseguridad u otro problema | N2: No indicado | O2: No indicado o no aplica | P2: X | S2: X | U2: X | W2: =IF(AND(P2="X",OR(R2="X",S2="X",T2="X")),"Sí","No") -> Sí | X2: X | AL2: No | AM2: No | AN2: No | AO2: Datos sintéticos | AP2: Exactitud 89,1 % | AQ2: Abstract | AR2: The rise in large-scale data breaches has increased the circulation of stolen Personally Identifiable Information (PII) across anonymized dark web ecosystems, where conventional monitoring tools have limited visibility. Ethical analysis of such environments is further constrained by legal restrictions and the absence of reproducible, open-source research frameworks. This paper presents a hybrid OSINT-based Dark Web Intelligence System designed to ethically detect exposed PII using a multistage pipeline integrating Tor-based anonymous crawling, automated text extraction, and a hybrid detection engine combining Regular Expressions, Named Entity Recognition (NER), and Microsoft Presidio. The system incorporates HMAC-SHA256 hashing for privacy-preserving storage and a modular visualization dashboard for real-time analysis. Evaluation on synthetically generated datasets demonstrated an overall accuracy of 89.1%, outperforming single method approaches by up to 15%. The proposed framework addresses critical gaps in ethical dark web research, offering a scalable, transparent, and academically reproducible approach to early breach detection and cybersecurity threat intelligence. © 2026 IEEE.
A3: S002 | B3: Pulickal E.; Kirtikar Y.; Dalvi T.; Rao A. | C3: 2025 | D3: SquidAct: Automated Custom Redaction | E3: Lecture Notes in Networks and Systems | F3: Conference paper | G3: 10.1007/978-981-96-3361-6_20 | H3: Núcleo | I3: N | J3: Herramienta de redacción de documentos Word y PDF con patrones y NLP, incluidos patrones definidos por el usuario. | K3: Núcleo | L3: Documentos generales | M3: General / documentos | N3: No indicado | O3: No indicado o no aplica | P3: X | R3: X | W3: =IF(AND(P3="X",OR(R3="X",S3="X",T3="X")),"Sí","No") -> Sí | AL3: No | AM3: No | AN3: No | AO3: No indicado | AP3: No reporta métricas cuantitativas | AQ3: Abstract | AR3: There is a critical need for a solution to protect sensitive data in an efficient, easy and automated manner. It is a common practice in various industries to obfuscate documents, however, existing software such as Adobe Acrobat Professional, ObjectiveRedact, and PDF element is either expensive, complex to use, or do not provide sufficient redaction features. The goal of our research is to create an automated redaction tool that can automatically detect and remove sensitive data in Word (.docx) and PDF (.pdf) documents. The tool will utilize pattern recognition algorithms and natural language processing techniques to redact sensitive information including custom user sensitive information. Minimizing the risk of data leakage, saving time, ensuring compliance with regulatory requirements, and allowing users to define their own custom sensitive data patterns to redact are some of the primary objectives of the tool. The tool also offers the users a preview and verification method which allows users to examine and improve redaction suggestions for better accuracy. This feature also promotes keeping the human element in the loop. Robust encryption methods have been put in place to safeguard documents that are being stored. © The Author(s), under exclusive license to Springer Nature Singapore Pte Ltd. 2025.
A4: S003 | B4: Mahammadli E.; Rustamov S. | C4: 2026 | D4: AzText: Curating Web-Scale Pretraining Data for a Low-Resource Language | E4: Communications in Computer and Information Science | F4: Conference paper | G4: 10.1007/978-3-032-31319-5_23 | H4: Excluido | I4: E3 | J4: La redacción de PII con regex es un paso menor de la curación de un corpus; el estudio no evalúa la detección. | K4: Complementario | L4: Corpus de preentrenamiento | M4: General / documentos | N4: Azerí | O4: Otra lengua | P4: X | W4: =IF(AND(P4="X",OR(R4="X",S4="X",T4="X")),"Sí","No") -> No | AL4: No | AM4: No | AN4: No | AO4: CulturaX, OSCAR, C4, Wikipedia | AP4: Perplejidad, exactitud HellaSwag | AQ4: Abstract | AR4: Large language models require large volumes of clean text for pretraining, yet low-resource languages such as Azerbaijani lack curated corpora of sufficient quality and scale. We present a multi-stage curation pipeline for Azerbaijani web text and report a systematic ablation study at n-gram scale. Starting from 14 million documents (4.66 billion tokens) drawn from five sources (CulturaX, OSCAR, C4, Wikipedia, and digitized books), the pipeline applies Unicode normalization, eight heuristic quality filters, ML-based scoring with language identification and n-gram language models (including KenLM), exact and MinHash near-deduplication, and regex-based PII redaction. The final corpus retains 9.5 million documents (3.0 billion tokens), i.e. 67.9% of documents and 64.4% of tokens. For internal comparison of corpus variants, we use n-gram perplexity and a translated Azerbaijani HellaSwag proxy as cheap surrogates; we treat these as screening signals rather than full evaluations of neural pretraining utility. Under this protocol, heuristic filters and deduplication each remove roughly one-sixth of documents. Digitized Azerbaijani books emerge as the most informative single source, and global MinHash deduplication yields a 0.8%-point accuracy gain over no deduplication at 3 billion training tokens. A corpus-trained SentencePiece tokenizer compresses Azerbaijani text 2.7× more efficiently than GPT-2. The contribution is the documented pipeline, the ablation evidence isolating each stage, and the released corpus and tokenizer, which together provide a reproducible starting point for transformer-based Azerbaijani pretraining. All code, the curated corpus, the SentencePiece tokenizer, and the HellaSwag-AZ evaluation set are released publicly. © The Author(s) 2026.
A5: S004 | B5: Pham D.; Kairouz P.; Mireshghallah N.; Bagdasarian E.; Pham C.M.; Houmansadr A. | C5: 2026 | D5: Can Large Language Models Really Recognize Your Name? | E5: ACM FAccT 2026 - Proceedings of the 9th annual ACM Conference on Fairness, Accountability, and Transparency | F5: Conference paper | G5: 10.1145/3805689.3806747 | H5: Núcleo | I5: N | J5: Muestra que los LLM pierden entre 20 % y 40 % de recall en nombres ambiguos; respalda no depender solo de un LLM para PER. | K5: Núcleo | L5: LLM / herramientas de privacidad | M5: LLM / asistentes | N5: Inglés | O5: Inglés | T5: X | W5: =IF(AND(P5="X",OR(R5="X",S5="X",T5="X")),"Sí","No") -> No | X5: X | AL5: No | AM5: No | AN5: No | AO5: AmBench (12.000 nombres ambiguos) | AP5: Recall por tipo de nombre | AQ5: Abstract | AR5: Large language models (LLMs) are increasingly being used in privacy pipelines to detect and remedy sensitive data leakage. These solutions often rely on the premise that LLMs can reliably recognize human names, one of the most important categories of personally identifiable information (PII). In this paper, we reveal how LLMs can consistently mishandle broad classes of human names even in short text snippets due to ambiguous linguistic cues in the contexts. We construct AmBench, a benchmark of over 12,000 real yet ambiguous human names based on the name regularity bias phenomenon. Each name appears in dozens of concise text snippets that are compatible with multiple entity types. Our experiments with 12 state-of-the-art LLMs show that the recall of AmBench names drops by 20-40% compared to more recognizable names. This uneven privacy protection due to linguistic properties raises important concerns about the fairness of privacy enforcement. When the contexts contain benign prompt injections - instruction-like user texts that can cause LLMs to conflate data with commands - AmBench names can become four times more likely to be ignored in Clio, an LLM-powered enterprise tool used by Anthropic AI to extract supposedly privacy-preserving insights from user conversations with Claude. Our findings showcase blind spots in the performance and fairness of LLM-based privacy solutions and call for a systematic investigation into their privacy failure modes and countermeasures. © 2026 Copyright held by the owner/author(s).
A6: S005 | B6: Mortadi A.; Nazih W.; Eldesouki M.I.; Hifny Y. | C6: 2025 | D6: Intelligent De-Identification of Medical Discharge Summaries Using Hybrid NLP Techniques | E6: ACM Transactions on Asian and Low-Resource Language Information Processing | F6: Article | G6: 10.1145/3724118 | H6: Núcleo | I6: N | J6: Desidentificación híbrida con NER, regex y listas de nombres y direcciones. | K6: Núcleo | L6: Clínico | M6: Salud / clínico | N6: Inglés | O6: Inglés | P6: X | Q6: X | R6: X | W6: =IF(AND(P6="X",OR(R6="X",S6="X",T6="X")),"Sí","No") -> Sí | X6: X | AA6: X | AL6: No | AM6: No | AN6: No | AO6: Resúmenes de alta sintéticos, OntoNotes, CoNLL-2003 | AP6: Desempeño de desidentificación | AQ6: Abstract | AR6: Medical discharge summaries are vital documents in healthcare, often containing Personally Identifiable Information (PII), raising concerns regarding privacy and regulatory compliance. This article proposes a cutting-edge approach that utilizes intelligent data de-identification to address this challenge. This article employs Natural Language Processing (NLP) techniques such as Named Entity Recognition (NER), a hybrid approach that integrates Machine Learning (ML) models, Regular Expressions (REGEX)-based recognizers, and extensive lists of names and addresses. The proposed method focuses on achieving a delicate balance between extracting valuable insights from data and safeguarding sensitive information. The evaluation against benchmarks demonstrates significant improvements in de-identification performance, particularly in discharge summaries. We present findings from our system’s evaluation of synthesized discharge summaries, the OntoNotes dataset, and the CoNLL-2003 dataset, demonstrating its effectiveness in anonymizing diverse medical text sources. © 2025 Copyright held by the owner/author(s).
A7: S006 | B7: Jabbarpour A.; Moulton E.; Kaviani S.; Ghassel S.; Zeng W.; Akbarian R.; Couture A.; Roy A.; Liu R.; Lucinian Y.A.; Hejji N.; AlSulaiman S.; Shirazi F.; Leung E.; Bonsall S.; Arfin S.; Gray B.G.; Klein R. | C7: 2025 | D7: Correction: On the construction of a large-scale database of AI-assisted annotating lung ventilation-perfusion scintigraphy for pulmonary embolism (VQ4PEDB) (Frontiers in Nuclear Medicine, (2025), 5, (1632112), 10.3389/fnume.2025.1632112) | E7: Frontiers in Nuclear Medicine | F7: Erratum | G7: 10.3389/fnume.2025.1671281 | H7: Excluido | I7: E1 | J7: Fe de erratas de otro artículo; no es un estudio. | K7: Excluido | L7: Clínico | M7: Salud / clínico | N7: No aplica | O7: No indicado o no aplica | W7: =IF(AND(P7="X",OR(R7="X",S7="X",T7="X")),"Sí","No") -> No | AL7: No | AM7: No | AN7: No | AO7: - | AP7: - | AQ7: Abstract | AR7: We have incorrectly opined about the performance of a private company's third party software. The performance related to Canadian zip codes as well as other types of data was due to a user error and improper configuration of the tool by the authors. We have made the following edits: A correction has been made to the section “Methods, Anonymization of DICOM files and de-identification of clinical reports, second paragraph”. The correct paragraph reads: “For clinical report texts, we adopted and compounded the effect of the following three independent approaches as a conservative de-identification strategy: (1) Segmed Inc.'s Python-based web server was used to remove PII/PHI from clinical reports, (2) RegEx rules were used to remove Canadian formatted addresses and postal codes in Python, and (3) resulting texts were fed to a Microsoft Copilot agent that was instructed to list suspected people names, addresses, street names, 5–8 digit numbers, business names, clinic names and occupations. The agent was further prompted to ignore medical terms. The resulting terms were then manually screened for relevance, the terms were searched for in the text and then replaced with “[Anon]”.” A correction has been made to the section “Discussion, Data Ingestion, first paragraph”. The correct paragraph reads: “QA revealed our unstructured text data to be properly de-identified, highlighting the effectiveness of our multiple layers of de-identification approaches. Structured DICOM data from hospital sources proved straightforward to robustly de-identify using our strategy. Also, during our QA process, various non-structured DICOM tags, such as series description, used during splitting process were identified and addressed accordingly to preserve integrity of workflow.” Original reference 27 has been removed. The original version of this article has been updated. 2025 Jabbarpour, Moulton, Kaviani, Ghassel, Zeng, Akbarian, Couture, Roy, Liu, Lucinian, Hejji, AlSulaiman, Shirazi, Leung, Bonsall, Arfin, Gray and Klein.
A8: S007 | B8: Mírovský J.; Novotná T.; Hladká B. | C8: 2025 | D8: MasKIT-Anonymization and Pseudonymization of Czech Legal Texts | E8: Jazykovedny Casopis | F8: Article | G8: 10.2478/jazcas-2025-0017 | H8: Núcleo | I8: N | J8: Anonimiza y seudonimiza textos jurídicos con NER externo y reglas sobre el análisis sintáctico. | K8: Núcleo | L8: Legal | M8: Legal / policial | N8: Checo | O8: Otra lengua | P8: X | R8: X | W8: =IF(AND(P8="X",OR(R8="X",S8="X",T8="X")),"Sí","No") -> Sí | AL8: No | AM8: No | AN8: No | AO8: Textos jurídicos | AP8: No reporta métricas en el abstract | AQ8: Abstract | AR8: MasKIT is a command-line tool, an on-line web application and a REST API service for anonymization and pseudonymization of Czech legal texts. Taking a plain text as input (e.g. a letter sent by a legal authority to a citizen), it runs external services for dependency parsing and named entity recognition and then via a rule-based approach identifies and replaces sensitive information in the text. © 2025 Jiří Mírovský et al., published by Slovak Academy of Sciences, Ľudovít Štúr Institute of Linguistics.
A9: S008 | B9: Dinesh M.; Aswin A.S.; Kannimoola J.M. | C9: 2025 | D9: Detection and Redaction of Sensitive Data in Application Logs using LLMs | E9: Proceedings of 5th International Conference on Pervasive Computing and Social Networking, ICPCSN 2025 | F9: Conference paper | G9: 10.1109/ICPCSN65854.2025.11034933 | H9: Núcleo | I9: N | J9: LLM ajustado para NER de datos sensibles en logs; argumenta los falsos positivos de las regex en formatos variables. | K9: Núcleo | L9: Software / logs | M9: Software / secretos técnicos | N9: No indicado | O9: No indicado o no aplica | T9: X | W9: =IF(AND(P9="X",OR(R9="X",S9="X",T9="X")),"Sí","No") -> No | AL9: No | AM9: No | AN9: No | AO9: Logs de aplicaciones | AP9: No reporta métricas en el abstract | AQ9: Abstract | AR9: Any public organization that collects or processes client or user data is legally required to protect this information, ensuring that it is not retained, shared, or stored anywhere as plain text. Logs, which aggregate data from multiple systems and services that an organization uses, can unintentionally include sensitive information. Conventional rule-based approaches and regular expressions (regex) to extract Personally Identifiable Information from logs can sometimes be inefficient. They cannot be easily adapted to varying log formats and face high false positives. This work proposes a system using a Large Language Model fine tuned for Named Entity Recognition task to identify sensitive items in logs coupled with a redaction module that encrypts the identified entities to generate tokens that can be used to replace the sensitive data. This system can reduce false positives, be adapted to varying log formats and is more secure thus ensuring privacy without compromising practicality. © 2025 IEEE.
A10: S009 | B10: Kvasnica P. | C10: 2025 | D10: Unstructured documents processing through their anonymization | E10: Journal of Electrical Engineering | F10: Article | G10: 10.2478/jee-2025-0028 | H10: Núcleo | I10: N | J10: Anonimización de decisiones judiciales con NER estadístico, diccionarios y reglas. | K10: Núcleo | L10: Legal | M10: Legal / policial | N10: Eslovaco | O10: Otra lengua | P10: X | Q10: X | R10: X | W10: =IF(AND(P10="X",OR(R10="X",S10="X",T10="X")),"Sí","No") -> Sí | AL10: No | AM10: No | AN10: No | AO10: Decisiones judiciales anotadas | AP10: No reporta métricas en el abstract | AQ10: Abstract | AR10: In Slovakia, a large number of texts on decisions are published by the courts on the MSSR website. All decisions that are published must be anonymous, without all personal and other data (personal and sensitive data that can identify individual entities in the proceedings, reveal their private data, etc.) to the extent described by the decree. Anonymization of court decision data is carried out according to an instruction given in the Court Management application, which supports only basic anonymization functions. Such an anonymization method is time- and human-resource-intensive, and at the same time, it is susceptible to the leakage of sensitive data. The text processing is based on machine learning methods using the principles of user-friendly visualization to accelerate anonymization and minimize the risk of leaking sensitive data. Achieving and improving results in practice the method of recognizing named entities based on the processing of text documents, dictionaries, rules and a trained statistical model on manually annotated data is used. The article describes the basic techniques of the anonymization used in practice, that are machine learning and removing information. Our attention is given to text documents processing, tools and principles for creating a data set of annotated data and evaluating the success of anonymization. The iteratively improving learning model is dominant in that it enables the use of knowledge as well as annotated data. © 2025 Peter Kvasnica, published by Sciendo.
A11: S010 | B11: Li Y.; Li C.; Wang Z.; Sui D.; Yan J. | C11: 2025 | D11: A Privacy-Preserving Framework for Medical Chatbot Based on LLM with Retrieval Augmented Generation | E11: Lecture Notes in Computer Science (including subseries Lecture Notes in Artificial Intelligence and Lecture Notes in Bioinformatics) | F11: Conference paper | G11: 10.1007/978-981-97-9437-9_2 | H11: Complementario | I11: C2 | J11: Marco de privacidad para un chatbot médico con RAG; el NER que anonimiza PII es un componente entre varios. | K11: Complementario | L11: Clínico / LLM | M11: LLM / asistentes | N11: No indicado | O11: No indicado o no aplica | R11: X | T11: X | W11: =IF(AND(P11="X",OR(R11="X",S11="X",T11="X")),"Sí","No") -> No | AL11: No | AM11: No | AN11: No | AO11: Base de conocimiento médica | AP11: No reporta métricas en el abstract | AQ11: Abstract | AR11: With the continuous advancement of Large Language Models (LLMs) and generative AI technologies, an increasing number of organizations are customizing and fine-tuning LLMs with internal data and documents to enhance the efficiency and reliability of data-driven decision-making. However, these approaches also present challenges in terms of data privacy, protection, and governance. In this paper, we investigate the implementation of privacy preservation in the construction of medical Knowledge Base Question Answering (KBQA) based on LLMs. We propose a solution involving fine-grained access control, the de-identification of sensitive data, and prompt engineering with Chain of Thought (CoT). Specifically, the visibility of information is determined based on user identity, and named entity recognition is employed to anonymize personally identifiable information. We also incorporate prompt engineering with Chain of Thought (CoT) to further enhance data privacy. Experimental study has demonstrated the effectiveness of our privacy protection framework. © The Author(s), under exclusive license to Springer Nature Singapore Pte Ltd. 2025.
A12: S011 | B12: Anselmo M.; Ribas B.C. | C12: 2025 | D12: Pseudonymization in Legal Texts According to the LGPD: A Named Entity Recognition Approach | E12: Lecture Notes in Computer Science (including subseries Lecture Notes in Artificial Intelligence and Lecture Notes in Bioinformatics) | F12: Conference paper | G12: 10.1007/978-3-031-79032-4_22 | H12: Núcleo | I12: N | J12: Transformer más regex para seudonimizar textos jurídicos según la LGPD, con datos sintéticos generados por LLM. | K12: Núcleo | L12: Legal | M12: Legal / policial | N12: Portugués | O12: Otra lengua | P12: X | S12: X | T12: X | W12: =IF(AND(P12="X",OR(R12="X",S12="X",T12="X")),"Sí","No") -> Sí | AL12: No | AM12: No | AN12: No | AO12: LeNER-Br y datos sintéticos de Llama 3 | AP12: No reporta valores en el abstract | AQ12: Abstract | AR12: This study explores the application of Named Entity Recognition (NER) for the pseudonymization of data in legal texts, aiming to protect Personally Identifiable Information (PII) in compliance with Brazil’s General Data Protection Law (LGPD). The research highlights the challenge of balancing data privacy and utility, presenting a methodology that uses artificial intelligence technologies to effectively identify and obscure PII in legal documents. In this study, we propose a Transformer model along with Regex techniques to identify entities in a text. To test the model, we created a new dataset from the existing LenerBR. We also used a function and prompt engineering applied to the Llama 8B version 3 model to generate synthetic data. Tests showed the need for further adjustments in the proposed new model. Future work will focus on improving the model’s accuracy and efficiency, as well as enhancing the identification of sensitive data and learning from user interactions. © The Author(s), under exclusive license to Springer Nature Switzerland AG 2025.
A13: S012 | B13: Le K.T.; Gärtner L.; Fleischle F.; Schöller T.; Große S.; Ulusoy I. | C13: 2026 | D13: mailcom: Pseudonymization tool for textual data | E13: SoftwareX | F13: Article | G13: 10.1016/j.softx.2026.102703 | H13: Núcleo | I13: N | J13: Paquete abierto de seudonimización (mailcom) como capa previa a la revisión humana. | K13: Núcleo | L13: Correos / humanidades digitales | M13: Software / secretos técnicos | N13: Multilingüe | O13: Multilingüe | R13: X | W13: =IF(AND(P13="X",OR(R13="X",S13="X",T13="X")),"Sí","No") -> No | AL13: No | AM13: No | AN13: No | AO13: No indicado | AP13: No reporta métricas en el abstract | AQ13: Abstract y documentación del repositorio (texto completo no disponible) | AR13: The rapid growth of data and its use has heightened concerns about data privacy. To support research on data that contains sensitive attributes, we developed the mailcom package for pseudonymization. mailcom is built entirely on open-source libraries and is designed for configurability and extensibility. Several languages are supported by default, with the option to add additional languages. Since pseudonymized outputs still require human review to guarantee full anonymization, the package serves as a scalable pre-processing layer that reduces manual work while establishing a principled baseline of privacy protection, enabling reproducible research on digital text under current data-ethics and governance standards. © 2026 The Author(s).
A14: S013 | B14: Parra Ariza A.J.; Rueda-Chacón H. | C14: 2026 | D14: Preserving Identity in Speech: Anonymized Transcription for the Colombian Context; [Preservando la Identidad en el Habla: Transcripción Anonimizada para el Contexto Colombiano] | E14: Procesamiento del Lenguaje Natural | F14: Article | G14: 10.26342/2026-76-16 | H14: Complementario | I14: C3 | J14: Anonimiza transcripciones de voz en español colombiano; es la única evidencia colombiana, pero el texto proviene de audio. | K14: Complementario | L14: Voz / transcripción | M14: Voz o imagen | N14: Español (Colombia) | O14: Español (solo o con otras lenguas) | R14: X | S14: X | W14: =IF(AND(P14="X",OR(R14="X",S14="X",T14="X")),"Sí","No") -> No | X14: X | AB14: X | AL14: No | AM14: No | AN14: No | AO14: Corpus de habla colombiano | AP14: WER 7,60 %; F1 NER 60,81 %; F1 anonimización 76,10 % | AQ14: Abstract | AR14: Speech has driven the development of Automatic Speech Recognition (ASR) models like Whisper, capable of converting spoken language into written text. However, these models require large amounts of data (corpora), which limits their performance in languages or variants with scarce resources, such as the Colombian Spanish, whose accents and regionalisms are underrepresented. Likewise, the use of recordings often includes sensitive information, such as names or IDs, which makes the collection and sharing of these corpora difficult. This work proposes the development of a model based on the Whisper arquitecture and WhisperX’s pipeline, for anonymized speech transcription in Colombian Spanish, with temporal annotation and speaker diarization. With models achieving a 7,60 % transcription word error rate (WER), an F1-score of 60,81 % for named entity recognition, and an F1-score of 76,10 % for anonymization, it contributes to closing the gap between existing models and Colombian dialects, ensuring robust performance even in low-resource settings. © 2026 Sociedad Española para el Procesamiento del Lenguaje Natural
A15: S014 | B15: Hassan F.; Sanchez D.; Domingo-Ferrer J. | C15: 2023 | D15: Utility-Preserving Privacy Protection of Textual Documents via Word Embeddings | E15: IEEE Transactions on Knowledge and Data Engineering | F15: Article | G15: 10.1109/TKDE.2021.3076632 | H15: Núcleo | I15: N | J15: Detecta términos reveladores con embeddings en vez de un conjunto fijo de entidades y reemplaza por generalizaciones; muestra el límite de las etiquetas fijas. | K15: Complementario | L15: Documentos generales | M15: General / documentos | N15: Inglés | O15: Inglés | V15: X | W15: =IF(AND(P15="X",OR(R15="X",S15="X",T15="X")),"Sí","No") -> No | AL15: No | AM15: Sí | AN15: No | AO15: Colecciones de documentos | AP15: Protección y utilidad frente a NER | AQ15: Abstract | AR15: Text is the most usual way to share information in society. Yet, if textual documents contain personal sensitive information, they cannot be shared with third parties or released publicly without adequate protection. Privacy-preserving mechanisms provide ways to sanitize data so that identities and/or confidential attributes are not disclosed. In the last twenty years, a great variety of mechanisms have been proposed to protect structured databases with numerical and categorical attributes; however, little attention has been devoted to unstructured textual data. In general, textual data protection requires first detecting pieces of text that may lead to disclosure of sensitive information and then masking those pieces via suppression or generalization. Current solutions rely on pre-trained classifiers that can recognize a fixed set of (allegedly disclosive) named entities, such as names or locations. Yet, such approaches fall short of providing adequate protection because in reality disclosive information is not limited to a predefined set of entity types, and not all the appearances of certain entity type result in disclosure. Besides, named entity recognition requires considerable manual effort to tag the training data needed to build classifiers. In this work we propose a more general and flexible solution for textual data protection. By means of word embeddings we build vectors that numerically capture the semantic relationships of the textual terms appearing in a collection of documents. Then we evaluate the disclosure caused by the textual terms on the entity to be protected (e.g., an individual's identity or a confidential attribute) according to the similarity between their vector representations. Our method also limits the semantic loss (and, therefore, the utility loss) of the document by replacing (rather than just suppressing) disclosive terms with privacy-preserving generalizations. Empirical results show that our approach offers much more robust protection and greater utility preservation than methods based on named entity recognition, with the additional important advantage of avoiding the burden of manual data tagging. © 1989-2012 IEEE.
A16: S015 | B16: Shettennavar S.B.; Sharma S.; Aswathy J.S.; Rakshitha K.S.; Karthika R. | C16: 2026 | D16: Offline Photo-Shield Automatic System for Finding and Redacting Privacy-Sensitive Information in Images | E16: Proceedings of the 6th International Conference on Pervasive Computing and Social Networking, ICPCSN 2026 | F16: Conference paper | G16: 10.1109/ICPCSN68523.2026.11543660 | H16: Complementario | I16: C3 | J16: Redacción en imágenes con OCR y regex, con puntaje de riesgo; aporta tipos de identificador pero la entrada no es texto. | K16: Excluido | L16: Imágenes | M16: Voz o imagen | N16: No indicado | O16: No indicado o no aplica | P16: X | V16: X | W16: =IF(AND(P16="X",OR(R16="X",S16="X",T16="X")),"Sí","No") -> No | Y16: X | Z16: X | AA16: X | AB16: X | AC16: X | AD16: X | AL16: No | AM16: No | AN16: No | AO16: Imágenes | AP16: Exactitud | AQ16: Abstract | AR16: The Photo-shield Automatic System presents a fully offline, AI-driven image redaction system for protecting sensitive information in digital images. This system automatically detects faces and text using EasyOCR and Media Pipe, respectively. The extracted text is analyzed using Python-based classifiers and REGEX techniques to identify privacy-critical entities. It recognizes Aadhaar, PAN numbers, phone numbers, email IDs, addresses, date of birth, financial details and vehicle registration plates. The detected faces and sensitive text regions are classified into predefined categories. Appropriate masking techniques, such as Gaussian blur or blackout are applied using OpenCV. This entire pipeline operates offline, ensuring data security and eliminating cloud dependency. A predefined risk-scoring module is used to evaluate the severity of privacy for each image. An automated PDF report of risk analysis summarizes the detected and redacted regions. The experimental results show high accuracy across multiple images and environment contexts. © 2026 IEEE.
A17: S016 | B17: Yao Z.; Hong K.; Wang X.; Ma J. | C17: 2026 | D17: Automatic Anonymization of Unstructured Text: Detecting Sensitive Information with Fine-Tuning Large Language Models | E17: 2026 4th International Conference on Big Data and Privacy Computing, BDPC 2026 | F17: Conference paper | G17: 10.1109/BDPC69980.2026.11608232 | H17: Núcleo | I17: N | J17: Compara LLM ajustados (Prefix Tuning y LoRA) con NER y reglas para anonimizar texto. | K17: Núcleo | L17: Texto no estructurado | M17: General / documentos | N17: No indicado | O17: No indicado o no aplica | P17: X | R17: X | T17: X | W17: =IF(AND(P17="X",OR(R17="X",S17="X",T17="X")),"Sí","No") -> Sí | AL17: No | AM17: No | AN17: No | AO17: No indicado | AP17: Desempeño de anonimización | AQ17: Abstract | AR17: In the age of digital connectivity, vast amounts of data are openly shared across social platforms, e-commerce platforms, and other online channels, potentially leading to inadvertent exposure of sensitive information. As a crucial mechanism for protecting sensitive information, anonymization techniques for structured data have already reached a relatively mature stage. Nevertheless, unstructured textual data lacks fixed structures and involves diverse entity types, making sensitive information difficult to identify through automated methods. Meanwhile, automated anonymization of unstructured text still relies heavily on manual processing, which is costly and inefficient, and thus requires further optimization. Presently, Large Language Models (LLMs) have demonstrated remarkable capabilities in semantic understanding and reasoning, but its effectiveness in anonymizing sensitive information within unstructured text still lacks systematic research. In this paper, we employ two fine-tuning approaches, namely Prefix Tuning and Low-Rank Adaptation (LoRA) Fine-Tuning, and verify that fine-tuned LLMs still achieve excellent performance in the task of anonymizing sensitive information in texts. Furthermore, we conduct a comparative evaluation and analyze their similarities and differences with traditional Named Entity Recognition (NER) and rule-based anonymization approaches. The evaluation results indicate that the fine-tuning model achieves outstanding performance in sensitive information anonymization tasks. © 2026 IEEE.
A18: S017 | B18: Albanese F.; Ronco P.; D'Ippolito N. | C18: 2026 | D18: Anonymous-by-Construction: An LLM-Driven Framework for Privacy-Preserving Text | E18: Proceedings - 2026 International Workshop on Responsible AI Engineering, RAIE 2026 | F18: Conference paper | G18: 10.1145/3786156.3788578 | H18: Núcleo | I18: N | J18: Sustitución local de PII antes de un LLM, comparada con Presidio y Google DLP; evalúa la calidad de las respuestas del agente. | K18: Núcleo | L18: Conversaciones / LLM | M18: LLM / asistentes | N18: Inglés | O18: Inglés | T18: X | U18: X | W18: =IF(AND(P18="X",OR(R18="X",S18="X",T18="X")),"Sí","No") -> No | X18: X | AL18: Sí | AM18: Sí | AN18: Sí | AO18: Action-Based Conversation Dataset | AP18: Recall de PII, utilidad semántica, calidad de respuestas del agente | AQ18: Abstract y texto completo | AR18: Responsible use of AI demands that we protect sensitive information without undermining the usefulness of data, an imperative that has become acute in the age of large language models. We address this challenge with an on-premise, LLM-driven substitution pipeline that anonymizes text by replacing personally identifiable information (PII) with realistic, type-consistent surrogates. Executed entirely within organizational boundaries using local LLMs, the approach prevents data egress while preserving fluency and task-relevant semantics.We conduct a systematic, multi-metric, cross-Technique evaluation on the Action-Based Conversation Dataset, benchmarking against industry standards (Microsoft Presidio and Google DLP) and a state-of-The-Art approach (ZSTS, in redaction-only and redaction-plus-substitution variants). Our protocol jointly measures privacy (PII recall), semantic utility (sentiment agreement, topic distance), and trainability under privacy via a lifecycle-ready criterion obtained by fine-Tuning a compact encoder (BERT+LoRA) on sanitized text. In addition, we assess agentic Q&A performance by inserting an on-premise anonymization layer before the answering LLM and evaluating the quality of its responses. This intermediate, type-preserving substitution stage ensures that no sensitive content is exposed to third-party APIs, enabling responsible deployment of Q&A agents without compromising confidentiality.Our method attains state-of-The-Art privacy, minimal topical drift, strong factual utility, and low trainability loss, outperforming rule-based approaches and named-entity recognition (NER) baselines and ZSTS variants on the combined privacy-utility-Trainability frontier. These results show that local LLM substitution yields anonymized corpora that are both responsible to use and operationally valuable: safe for agentic pipelines over conversational data and suitable for downstream fine-Tuning with limited degradation. By coupling on-premise anonymization with rigorous, auditable evaluation, this work offers decision-ready evidence for deploying Responsible-AI-by-Design systems in real-world settings. © 2026 Copyright held by the owner/author(s).
A19: S018 | B19: Berzi A.; Berényi E.; Képes Z.; Antal B.; Varga Á.G.; Emri M. | C19: 2025 | D19: NLP-based removal of personally identifiable information from Hungarian electronic health records | E19: Frontiers in Artificial Intelligence | F19: Article | G19: 10.3389/frai.2025.1585260 | H19: Núcleo | I19: N | J19: Modelos spaCy para PII en historias clínicas, con pre-anotación por reglas; muestra el uso de pre-anotación. | K19: Núcleo | L19: Clínico | M19: Salud / clínico | N19: Húngaro | O19: Otra lengua | P19: X | R19: X | W19: =IF(AND(P19="X",OR(R19="X",S19="X",T19="X")),"Sí","No") -> Sí | AL19: No | AM19: No | AN19: No | AO19: 15.000 historias clínicas, 90.000 PII | AP19: F1 0,970–0,993; 99,67 % de PII removida | AQ19: Abstract | AR19: Introduction: Electronic health records (EHR) in text format serve as crucial resources for data-driven medical research. To safeguard patient confidentiality, under the General Data Protection Regulation (GDPR), strict measures are required to ensure personal data is anonymized or pseudonymized to protect individual privacy. Natural language processing has consistently proven effective in automating the de-identification of sensitive information. Methods: We present spaCy models to recognize personally identifiable information (PII) from a wide range of free-text medical records written in Hungarian, a low-resource language. To develop this model, we compiled a corpus of clinical documents by annotating sensitive information within electronic health records sourced from the University of Debrecen. To simplify the annotation process, we pre-annotated the documents using a rule-based method. The corpora comprises over 15,000 documents and includes more than 90,000 instances of PII. We trained several models using this corpus and also developed a separate validation corpus to assess their performance. Results: The performance evaluation of the de-identification models on the developed corpora resulted in F1-scores ranging from 0.9697 to 0.9926. On the validation corpora, the F1-scores ranged from 0.9772 to 0.9867, demonstrating that the models can effectively handle previously unseen examples. Our risk analysis revealed that 99.67% of the sensitive information was successfully removed from the validation dataset. Discussion: The results indicate that similarly to other state-of-the-art systems our model is highly effective at identifying PII in clinical texts, guaranteeing that sensitive information in clinical documents can be protected without sacrificing the quality or usability of the data for research purposes. Despite these positive outcomes, several areas remain to be improved, such as the conduction of additional testing on diverse datasets, particularly those from different healthcare institutions. With ongoing refinements, these models have the potential to greatly enhance the efficiency of data de-identification processes, ensuring compliance with privacy regulations while promoting the secure sharing of medical data for scientific progress. Copyright © 2025 Berzi, Berényi, Képes, Antal, Varga and Emri.
A20: S019 | B20: Ren L.; Belkadi S.; Han L.; Del-Pinto W.; Nenadic G. | C20: 2025 | D20: Synthetic4Health: generating annotated synthetic clinical letters | E20: Frontiers in Digital Health | F20: Article | G20: 10.3389/fdgth.2025.1497130 | H20: Complementario | I20: C1 | J20: Genera cartas clínicas sintéticas desidentificadas; aporta a la generación de datos sintéticos, no a la detección. | K20: Complementario | L20: Clínico | M20: Salud / clínico | N20: Inglés | O20: Inglés | S20: X | T20: X | W20: =IF(AND(P20="X",OR(R20="X",S20="X",T20="X")),"Sí","No") -> No | AL20: No | AM20: Sí | AN20: No | AO20: Cartas clínicas | AP20: BERTScore y NER aguas abajo | AQ20: Abstract | AR20: Clinical letters contain sensitive information, limiting their use in model training, medical research, and education. This study aims to generate reliable, diverse, and de-identified synthetic clinical letters to support these tasks. We investigated multiple pre-trained language models for text masking and generation, focusing on Bio_ClinicalBERT, and applied different masking strategies. Evaluation included qualitative and quantitative assessments, downstream named entity recognition (NER) tasks, and clinically focused evaluations using BioGPT and GPT-3.5-turbo. The experiments show: (1) encoder-only models perform better than encoder–decoder models; (2) models trained on general corpora perform comparably to clinical-domain models if clinical entities are preserved; (3) preserving clinical entities and document structure aligns with the task objectives; (4) Masking strategies have a noticeable impact on the quality of synthetic clinical letters: masking stopwords has a positive impact, while masking nouns or verbs has a negative effect; (5) The BERTScore should be the primary quantitative evaluation metric, with other metrics serving as supplementary references; (6) Contextual information has only a limited effect on the models' understanding, suggesting that synthetic letters can effectively substitute real ones in downstream NER tasks; (7) Although the model occasionally generates hallucinated content, it appears to have little effect on overall clinical performance. Unlike previous research, which primarily focuses on reconstructing original letters by training language models, this paper provides a foundational framework for generating diverse, de-identified clinical letters. It offers a direction for utilizing the model to process real-world clinical letters, thereby helping to expand datasets in the clinical domain. Our codes and trained models are available at https://github.com/HECTA-UoM/Synthetic4Health. 2025 Ren, Belkadi, Han, Del-Pinto and Nenadic.
A21: S020 | B21: Arthy S.; Sakthi Priya G. | C21: 2025 | D21: A Hybrid Machine Learning Approach for Securing Emails:Phishing Detection and Prevention | E21: 2025 3rd International Conference on Advancements in Electrical, Electronics, Communication, Computing and Automation, ICAECA 2025 | F21: Conference paper | G21: 10.1109/ICAECA63854.2025.11012305 | H21: Excluido | I21: E2 | J21: El problema es la detección de phishing; el NER se usa para validar entidades del correo. | K21: Excluido | L21: Correo / phishing | M21: Ciberseguridad u otro problema | N21: No indicado | O21: No indicado o no aplica | P21: X | R21: X | S21: X | W21: =IF(AND(P21="X",OR(R21="X",S21="X",T21="X")),"Sí","No") -> Sí | AL21: No | AM21: No | AN21: No | AO21: Correos | AP21: Exactitud de detección de phishing | AQ21: Abstract | AR21: Email phishing is a cyberattack in which an attacker sends fraudulent emails that appear to be from legitimate sources. The intension of phishing attack is to deceive the recipient into disclosing sensitive information, such as passwords, credit card numbers, or personal information, or into clicking on malicious links or downloading malware. These emails frequently employ social engineering tactics to infuse a sense of urgency or fear in users, prompting them to take immediate action without verifying the message's authenticity. Phishing attacks continue to be a major security threat in email communication, necessitating advanced methods for detection. This paper introduces an innovative phishing detection email extension that integrates Neuro-Symbolic AI, Dynamic Contextual Analysis (DCA), and Memory-Augmented Neural Networks (MANNs) to effectively identify and block phishing attempts in real-time. The extension leverages a Neuro-Symbolic Hybrid Model(NSHM) that combines rule-based reasoning with deep learning to analyse email content and flag suspicious elements. Dynamic Contextual Analysis enhances the detection by evaluating sender behavior, metadata, and email timing to spot anomalies in email interactions. Additionally, Memory-Augmented Neural Networks allow the system to retain knowledge of past phishing patterns, enabling it to adapt to emerging and sophisticated phishing strategies. The email extension incorporates Named Entity Recognition (NER) to detect and validate key entities (such as organizations, URLs), and Domain Reputation Analysis to assess the legitimacy of links embedded in emails. To ensure transparency and user trust, explainability techniques like LIME (Local Interpretable Model-Agnostic Explanations) and SHAP (SHapley Additive exPlanations) are integrated, providing users with insights into why an email is classified as phishing. Experimental results show that this extension significantly improves phishing detection accuracy, reduces false positives, and provides an intuitive and secure user experience for real-time email protection. © 2025 IEEE.
A22: S021 | B22: Dai J.; Li H. | C22: 2026 | D22: Pixel-Level Privacy Preserving in DICOM Anonymisation | E22: Lecture Notes of the Institute for Computer Sciences, Social-Informatics and Telecommunications Engineering, LNICST | F22: Conference paper | G22: 10.1007/978-3-032-14350-1_14 | H22: Complementario | I22: C3 | J22: Anonimización de DICOM con OCR y NER; la entrada es imagen. | K22: Excluido | L22: Imágenes médicas | M22: Voz o imagen | N22: No indicado | O22: No indicado o no aplica | R22: X | V22: X | W22: =IF(AND(P22="X",OR(R22="X",S22="X",T22="X")),"Sí","No") -> No | AL22: No | AM22: No | AN22: No | AO22: Archivos DICOM | AP22: No reporta métricas en el abstract | AQ22: Abstract | AR22: DICOM (Digital Imaging and Communications in Medicine) is a standard format for medical images, often containing sensitive patient information. To protect patient privacy, anonymizing DICOM files before sharing or storage is essential, this work introduces a novel DICOM medical image anonymization approach that employs Optical Character Recognition (OCR) to identify personally identifiable information (PII) within both tags and textual content embedded within images. By employing Named Entity Recognition (NER) techniques, the system accurately detects PII in textual data. The proposed method operates independently of metadata, enabling the anonymization of sensitive information in both tags and pixel-level image content. This approach can help efficient and automated anonymization of medical image files, significantly enhancing patient privacy. © ICST Institute for Computer Sciences, Social Informatics and Telecommunications Engineering 2026.
A23: S022 | B23: Asiri S.; Alshehri R.; Kamran F.; Laznam H.; Xiao Y.; Alzahrani S. | C23: 2025 | D23: SPADR: A Context-Aware Pipeline for Privacy Risk Detection in Text Data | E23: Electronics (Switzerland) | F23: Article | G23: 10.3390/electronics14183725 | H23: Núcleo | I23: N | J23: Detecta riesgos explícitos y contextuales en correos con NER, autoencoder y grafos; fuente de la métrica de fuga residual. | K23: Núcleo | L23: Correo corporativo | M23: Empresarial | N23: Inglés | O23: Inglés | R23: X | V23: X | W23: =IF(AND(P23="X",OR(R23="X",S23="X",T23="X")),"Sí","No") -> No | AL23: Sí | AM23: Sí | AN23: No | AO23: Enron Email Dataset | AP23: Fuga residual de 100 % a 16,06 %; BERTScore F1 88,03 % | AQ23: Abstract y texto completo | AR23: Large language models (LLMs) are powerful, but they can unintentionally memorize and leak sensitive information found in their training or input data. To address this issue, we propose SPADR, a semantic privacy anomaly detection and remediation pipeline designed to detect and remove privacy risks from text. SPADR addresses limitations in existing redaction methods by identifying deeper forms of sensitive content, including implied relationships, contextual clues, and non-standard identifiers that traditional NER systems often overlook. SPADR combines semantic anomaly scoring using a denoising autoencoder with named entity recognition and graph-based analysis to detect both direct and hidden privacy risks. It is flexible enough to work on both training data (to prevent memorization) and user input (to prevent leakage at inference time). We evaluate SPADR on the Enron Email Dataset, where it significantly reduces document-level privacy leakage while maintaining strong semantic utility. The enhanced version, SPADR (S2), reduces the PII leak rate from 100% to 16.06% and achieves a BERTScore F1 of 88.03%. Compared to standard NER-based redaction systems, SPADR offers more accurate and context-aware privacy protection. This work highlights the importance of semantic and structural understanding in building safer, privacy-respecting AI systems. © 2025 by the authors.
